<mujoco model="hand_palm">
  <compiler angle="radian" meshdir="meshes"/>
  <option gravity="0 0 -9.81"/>
  <asset>
    <mesh name="hand_palm_0" file="hand_palm.stl" scale="0.01 0.01 0.01"/>
    <mesh name="new_link_5_1" file="new_link_5.stl" scale="0.01 0.01 0.01"/>
    <mesh name="new_link_8_2" file="new_link_8.stl" scale="0.01 0.01 0.01"/>
    <mesh name="new_link_12_3" file="new_link_12.stl" scale="0.01 0.01 0.01"/>
    <mesh name="new_link_6_4" file="new_link_6.stl" scale="0.01 0.01 0.01"/>
    <mesh name="new_link_9_5" file="new_link_9.stl" scale="0.01 0.01 0.01"/>
    <mesh name="new_link_13_6" file="new_link_13.stl" scale="0.01 0.01 0.01"/>
    <mesh name="new_link_7_7" file="new_link_7.stl" scale="0.01 0.01 0.01"/>
    <mesh name="new_link_10_8" file="new_link_10.stl" scale="0.01 0.01 0.01"/>
    <mesh name="new_link_14_9" file="new_link_14.stl" scale="0.01 0.01 0.01"/>
    <mesh name="index_finger-1st-pitch_10" file="index_finger-1st-pitch.stl" scale="0.01 0.01 0.01"/>
    <mesh name="index_finger-2st-pitch_11" file="index_finger-2st-pitch.stl" scale="0.01 0.01 0.01"/>
    <mesh name="index_finger-3st-pitch_12" file="index_finger-3st-pitch.stl" scale="0.01 0.01 0.01"/>
    <mesh name="thumb-link_13" file="thumb-link.stl" scale="0.01 0.01 0.01"/>
    <mesh name="new_link_11_14" file="new_link_11.stl" scale="0.01 0.01 0.01"/>
    <mesh name="new_link_15_15" file="new_link_15.stl" scale="0.01 0.01 0.01"/>
    <mesh name="little_finger-1st_roll_join_16" file="little_finger-1st_roll_join.stl" scale="0.01 0.01 0.01"/>
    <mesh name="ring_finger-1st_roll_join_17" file="ring_finger-1st_roll_join.stl" scale="0.01 0.01 0.01"/>
    <mesh name="middle_finger_1st_roll_join_18" file="middle_finger_1st_roll_join.stl" scale="0.01 0.01 0.01"/>
    <mesh name="index_finger_1st_roll_join_19" file="index_finger_1st_roll_join.stl" scale="0.01 0.01 0.01"/>
    <mesh name="thumb_1st_yaw_join_20" file="thumb_1st_yaw_join.stl" scale="0.01 0.01 0.01"/>
    <material name="gray" rgba="0.5 0.5 0.5 1"/>
    <material name="collision" rgba="1 0 0 0.5"/>
  </asset>
  <worldbody>
    <light diffuse=".5 .5 .5" pos="0 0 3" dir="0 0 -1"/>
    <geom type="plane" size="5 5 0.1" rgba=".9 .9 .9 1"/>
    <body name="hand_palm" pos="0 0 0" euler="0 0 0">
      <geom type="mesh" mesh="hand_palm_0" group="1" contype="0" conaffinity="0" pos="0.0 0.0 0.0" euler="1.5707963267948966 -3.141592653589793 1.5707963267948966" rgba="0.941 0.941 0.941 1.0" />
      <geom type="cylinder" size="0.012 0.02" pos="0.02 0 0" euler="0 1.5708 0" group="0" rgba="0 0 1 0.4" />
      <body name="new_link" pos="0.16 0.369 0.843" euler="-0.17453292519943295 0.0 0.0">
        <joint name="LittleFinger-1st_roll" type="hinge" axis="1 0 0" range="-0.17453292519943295 0.17453292519943295" />
        <geom type="mesh" mesh="little_finger-1st_roll_join_16" pos="0.0 0.0 0.0" euler="-1.5707963267948966 0.0 -1.5707963267948966" rgba="0.941 0.941 0.941 1.0" group="1" />
        <geom type="mesh" mesh="little_finger-1st_roll_join_16" pos="0.0 0.0 0.0" euler="-1.5707963267948966 0.0 -1.5707963267948966" group="0" rgba="1 0 0 0" />
        <body name="new_link_5" pos="0.0 0.0 0.0" euler="0.0 0.0 0.0">
          <joint name="LittleFinger-1st-pitch" type="hinge" axis="0 1 0" range="-1.5707963267948966 0.0" />
          <geom type="mesh" mesh="new_link_5_1" group="1" contype="0" conaffinity="0" pos="0.0 0.0 0.0" euler="-1.5707963267948966 0.0 -1.5707963267948966" rgba="0.941 0.941 0.941 1.0" />
          <geom type="cylinder" size="0.012 0.02" pos="0.02 0 0" euler="0 1.5708 0" group="0" rgba="0 0 1 0.4" />
          <body name="new_link_8" pos="0.035 0.0 0.41" euler="0.0 0.0 0.0">
            <joint name="LittleFinger-2nd-pitch" type="hinge" axis="0 1 0" range="-1.5707963267948966 0.0" />
            <geom type="mesh" mesh="new_link_8_2" group="1" contype="0" conaffinity="0" pos="0.0 0.0 0.0" euler="-1.5707963267948966 0.0 -1.5707963267948966" rgba="0.941 0.941 0.941 1.0" />
            <geom type="cylinder" size="0.012 0.02" pos="0.02 0 0" euler="0 1.5708 0" group="0" rgba="0 0 1 0.4" />
            <body name="new_link_12" pos="0.008 0.0 0.209" euler="0.0 0.0 0.0">
              <joint name="LittleFinger-3rd-pitch" type="hinge" axis="0 1 0" range="-1.5707963267948966 0.0" />
              <geom type="mesh" mesh="new_link_12_3" group="1" contype="0" conaffinity="0" pos="0.0 0.0 0.0" euler="-1.5707963267948966 0.0 -1.5707963267948966" rgba="0.941 0.941 0.941 1.0" />
              <geom type="cylinder" size="0.012 0.02" pos="0.02 0 0" euler="0 1.5708 0" group="0" rgba="0 0 1 0.4" />
              <site name="Little_sensor_0_1" pos="0.03   0.03   0.275" size="0.01" rgba="1 0 0 1"/>
              <site name="Little_sensor_0_2" pos="0.03   0      0.28 " size="0.01" rgba="1 0 0 1"/>
              <site name="Little_sensor_0_3" pos="0.03   -0.03  0.275" size="0.01" rgba="1 0 0 1"/>
              <site name="Little_sensor_1_1" pos="0      0.03   0.275" size="0.01" rgba="1 0 0 1"/>
              <site name="Little_sensor_1_2" pos="0      0      0.275" size="0.01" rgba="1 0 0 1"/>
              <site name="Little_sensor_1_3" pos="0      -0.03  0.275" size="0.01" rgba="1 0 0 1"/>
              <site name="Little_sensor_2_1" pos="-0.03  0.03   0.26"  size="0.01" rgba="1 0 0 1"/>
              <site name="Little_sensor_2_2" pos="-0.03  0      0.26"  size="0.01" rgba="1 0 0 1"/>
              <site name="Little_sensor_2_3" pos="-0.03  -0.03  0.26"  size="0.01" rgba="1 0 0 1"/>
              <site name="Little_sensor_3_1" pos="-0.045 0.03   0.23"  size="0.01" rgba="1 0 0 1"/>
              <site name="Little_sensor_3_2" pos="-0.045 0      0.23"  size="0.01" rgba="1 0 0 1"/>
              <site name="Little_sensor_3_3" pos="-0.045 -0.03  0.23"  size="0.01" rgba="1 0 0 1"/>
              <site name="Little_sensor_4_1" pos="-0.05  0.03   0.2"   size="0.01" rgba="1 0 0 1"/>
              <site name="Little_sensor_4_2" pos="-0.05  0      0.2"   size="0.01" rgba="1 0 0 1"/>
              <site name="Little_sensor_4_3" pos="-0.05  -0.03  0.2"   size="0.01" rgba="1 0 0 1"/>
              <site name="Little_sensor_5_1" pos="-0.06  0.03   0.17"  size="0.01" rgba="1 0 0 1"/>
              <site name="Little_sensor_5_2" pos="-0.06  0      0.17"  size="0.01" rgba="1 0 0 1"/>
              <site name="Little_sensor_5_3" pos="-0.06  -0.03  0.17"  size="0.01" rgba="1 0 0 1"/>
              <site name="Little_sensor_6_1" pos="-0.065 0.03   0.14"  size="0.01" rgba="1 0 0 1"/>
              <site name="Little_sensor_6_2" pos="-0.065 0      0.14"  size="0.01" rgba="1 0 0 1"/>
              <site name="Little_sensor_6_3" pos="-0.065 -0.03  0.14"  size="0.01" rgba="1 0 0 1"/>                       
            </body>
          </body>
        </body>
      </body>
      <body name="new_link_1" pos="0.16 0.14800000000000002 0.9229999999999999" euler="-0.08726646259971647 0.0 0.0">
        <joint name="RingFinger-1st_roll" type="hinge" axis="1 0 0" range="-0.17453292519943295 0.17453292519943295" />
        <geom type="mesh" mesh="ring_finger-1st_roll_join_17" pos="0.0 0.0 0.0" euler="-1.5707963267948966 0.0 -1.5707963267948966" rgba="0.941 0.941 0.941 1.0" group="1" />
        <geom type="mesh" mesh="ring_finger-1st_roll_join_17" pos="0.0 0.0 0.0" euler="-1.5707963267948966 0.0 -1.5707963267948966" group="0" rgba="1 0 0 0" />
        <body name="new_link_6" pos="0.0 0.0 0.0" euler="0.0 0.0 0.0">
          <joint name="RingFinger-1st-pitch" type="hinge" axis="0 1 0" range="-1.5707963267948966 0.0" />
          <geom type="mesh" mesh="new_link_6_4" group="1" contype="0" conaffinity="0" pos="0.0 0.0 0.0" euler="-1.5707963267948966 0.0 -1.5707963267948966" rgba="0.941 0.941 0.941 1.0" />
          <geom type="cylinder" size="0.012 0.02" pos="0.02 0 0" euler="0 1.5708 0" group="0" rgba="0 0 1 0.4" />
          <body name="new_link_9" pos="0.035 0.0 0.41" euler="0.0 0.0 0.0">
            <joint name="RingFinger-2nd-pitch" type="hinge" axis="0 1 0" range="-1.5707963267948966 0.0" />
            <geom type="mesh" mesh="new_link_9_5" group="1" contype="0" conaffinity="0" pos="0.0 0.0 0.0" euler="-1.5707963267948966 0.0 -1.5707963267948966" rgba="0.941 0.941 0.941 1.0" />
            <geom type="cylinder" size="0.012 0.02" pos="0.02 0 0" euler="0 1.5708 0" group="0" rgba="0 0 1 0.4" />
            <body name="new_link_13" pos="0.008 0.0 0.24" euler="0.0 0.0 0.0">
              <joint name="RingFinger-3rd-pitch" type="hinge" axis="0 1 0" range="-1.5707963267948966 0.0" />
              <geom type="mesh" mesh="new_link_13_6" group="1" contype="0" conaffinity="0" pos="0.0 0.0 0.0" euler="-1.5707963267948966 0.0 -1.5707963267948966" rgba="0.941 0.941 0.941 1.0" />
              <geom type="cylinder" size="0.012 0.02" pos="0.02 0 0" euler="0 1.5708 0" group="0" rgba="0 0 1 0.4" />
             
              <site name="Ring_sensor_0_1" pos="0.03   0.03   0.275" size="0.01" rgba="1 0 0 1"/>
              <site name="Ring_sensor_0_2" pos="0.03   0      0.28 " size="0.01" rgba="1 0 0 1"/>
              <site name="Ring_sensor_0_3" pos="0.03   -0.03  0.275" size="0.01" rgba="1 0 0 1"/>
              <site name="Ring_sensor_1_1" pos="0      0.03   0.275" size="0.01" rgba="1 0 0 1"/>
              <site name="Ring_sensor_1_2" pos="0      0      0.275" size="0.01" rgba="1 0 0 1"/>
              <site name="Ring_sensor_1_3" pos="0      -0.03  0.275" size="0.01" rgba="1 0 0 1"/>
              <site name="Ring_sensor_2_1" pos="-0.03  0.03   0.26"  size="0.01" rgba="1 0 0 1"/>
              <site name="Ring_sensor_2_2" pos="-0.03  0      0.26"  size="0.01" rgba="1 0 0 1"/>
              <site name="Ring_sensor_2_3" pos="-0.03  -0.03  0.26"  size="0.01" rgba="1 0 0 1"/>
              <site name="Ring_sensor_3_1" pos="-0.045 0.03   0.23"  size="0.01" rgba="1 0 0 1"/>
              <site name="Ring_sensor_3_2" pos="-0.045 0      0.23"  size="0.01" rgba="1 0 0 1"/>
              <site name="Ring_sensor_3_3" pos="-0.045 -0.03  0.23"  size="0.01" rgba="1 0 0 1"/>
              <site name="Ring_sensor_4_1" pos="-0.05  0.03   0.2"   size="0.01" rgba="1 0 0 1"/>
              <site name="Ring_sensor_4_2" pos="-0.05  0      0.2"   size="0.01" rgba="1 0 0 1"/>
              <site name="Ring_sensor_4_3" pos="-0.05  -0.03  0.2"   size="0.01" rgba="1 0 0 1"/>
              <site name="Ring_sensor_5_1" pos="-0.06  0.03   0.17"  size="0.01" rgba="1 0 0 1"/>
              <site name="Ring_sensor_5_2" pos="-0.06  0      0.17"  size="0.01" rgba="1 0 0 1"/>
              <site name="Ring_sensor_5_3" pos="-0.06  -0.03  0.17"  size="0.01" rgba="1 0 0 1"/>
              <site name="Ring_sensor_6_1" pos="-0.065 0.03   0.14"  size="0.01" rgba="1 0 0 1"/>
              <site name="Ring_sensor_6_2" pos="-0.065 0      0.14"  size="0.01" rgba="1 0 0 1"/>
              <site name="Ring_sensor_6_3" pos="-0.065 -0.03  0.14"  size="0.01" rgba="1 0 0 1"/>    

            </body>
          </body>
        </body>
      </body>
      <body name="new_link_2" pos="0.16 -0.08 0.955" euler="0.0 0.0 0.0">
        <joint name="MiddleFinger_1st_roll" type="hinge" axis="1 0 0" range="-0.17453292519943295 0.17453292519943295" />
        <geom type="mesh" mesh="middle_finger_1st_roll_join_18" pos="0.0 0.0 0.0" euler="-1.5707963267948966 0.0 -1.5707963267948966" rgba="0.941 0.941 0.941 1.0" group="1" />
        <geom type="mesh" mesh="middle_finger_1st_roll_join_18" pos="0.0 0.0 0.0" euler="-1.5707963267948966 0.0 -1.5707963267948966" group="0" rgba="1 0 0 0" />
        <body name="new_link_7" pos="0.0 0.0 0.0" euler="0.0 0.0 0.0">
          <joint name="MiddleFinger-1st-pitch" type="hinge" axis="0 1 0" range="-1.5707963267948966 0.0" />
          <geom type="mesh" mesh="new_link_7_7" group="1" contype="0" conaffinity="0" pos="0.0 0.0 0.0" euler="-1.5707963267948966 0.0 -1.5707963267948966" rgba="0.941 0.941 0.941 1.0" />
          <geom type="cylinder" size="0.012 0.02" pos="0.02 0 0" euler="0 1.5708 0" group="0" rgba="0 0 1 0.4" />
          <body name="new_link_10" pos="0.035 0.0 0.44" euler="0.0 0.0 0.0">
            <joint name="MiddleFinger-2nd-pitch" type="hinge" axis="0 1 0" range="-1.5707963267948966 0.0" />
            <geom type="mesh" mesh="new_link_10_8" group="1" contype="0" conaffinity="0" pos="0.0 0.0 0.0" euler="-1.5707963267948966 0.0 -1.5707963267948966" rgba="0.941 0.941 0.941 1.0" />
            <geom type="cylinder" size="0.012 0.02" pos="0.02 0 0" euler="0 1.5708 0" group="0" rgba="0 0 1 0.4" />
            <body name="new_link_14" pos="0.008 0.0 0.27" euler="0.0 0.0 0.0">
              <joint name="MiddleFinger-3rd-pitch" type="hinge" axis="0 1 0" range="-1.5707963267948966 -0.03490658503988659" />
              <geom type="mesh" mesh="new_link_14_9" group="1" contype="0" conaffinity="0" pos="0.0 0.0 0.0" euler="-1.5707963267948966 0.0 -1.5707963267948966" rgba="0.941 0.941 0.941 1.0" />
              <geom type="cylinder" size="0.012 0.02" pos="0.02 0 0" euler="0 1.5708 0" group="0" rgba="0 0 1 0.4" />

              <site name="Middle_sensor_0_1" pos="0.03   0.03   0.275" size="0.01" rgba="1 0 0 1"/>
              <site name="Middle_sensor_0_2" pos="0.03   0      0.28 " size="0.01" rgba="1 0 0 1"/>
              <site name="Middle_sensor_0_3" pos="0.03   -0.03  0.275" size="0.01" rgba="1 0 0 1"/>
              <site name="Middle_sensor_1_1" pos="0      0.03   0.275" size="0.01" rgba="1 0 0 1"/>
              <site name="Middle_sensor_1_2" pos="0      0      0.275" size="0.01" rgba="1 0 0 1"/>
              <site name="Middle_sensor_1_3" pos="0      -0.03  0.275" size="0.01" rgba="1 0 0 1"/>
              <site name="Middle_sensor_2_1" pos="-0.03  0.03   0.26"  size="0.01" rgba="1 0 0 1"/>
              <site name="Middle_sensor_2_2" pos="-0.03  0      0.26"  size="0.01" rgba="1 0 0 1"/>
              <site name="Middle_sensor_2_3" pos="-0.03  -0.03  0.26"  size="0.01" rgba="1 0 0 1"/>
              <site name="Middle_sensor_3_1" pos="-0.045 0.03   0.23"  size="0.01" rgba="1 0 0 1"/>
              <site name="Middle_sensor_3_2" pos="-0.045 0      0.23"  size="0.01" rgba="1 0 0 1"/>
              <site name="Middle_sensor_3_3" pos="-0.045 -0.03  0.23"  size="0.01" rgba="1 0 0 1"/>
              <site name="Middle_sensor_4_1" pos="-0.05  0.03   0.2"   size="0.01" rgba="1 0 0 1"/>
              <site name="Middle_sensor_4_2" pos="-0.05  0      0.2"   size="0.01" rgba="1 0 0 1"/>
              <site name="Middle_sensor_4_3" pos="-0.05  -0.03  0.2"   size="0.01" rgba="1 0 0 1"/>
              <site name="Middle_sensor_5_1" pos="-0.06  0.03   0.17"  size="0.01" rgba="1 0 0 1"/>
              <site name="Middle_sensor_5_2" pos="-0.06  0      0.17"  size="0.01" rgba="1 0 0 1"/>
              <site name="Middle_sensor_5_3" pos="-0.06  -0.03  0.17"  size="0.01" rgba="1 0 0 1"/>
              <site name="Middle_sensor_6_1" pos="-0.065 0.03   0.14"  size="0.01" rgba="1 0 0 1"/>
              <site name="Middle_sensor_6_2" pos="-0.065 0      0.14"  size="0.01" rgba="1 0 0 1"/>
              <site name="Middle_sensor_6_3" pos="-0.065 -0.03  0.14"  size="0.01" rgba="1 0 0 1"/>                  
            </body>
          </body>
        </body>
      </body>
      <body name="new_link_3" pos="0.16 -0.31 0.9229999999999999" euler="0.08726646259971647 0.0 0.0">
        <joint name="IndexFinger_1st_roll" type="hinge" axis="1 0 0" range="-0.17453292519943295 0.17453292519943295" />
        <geom type="mesh" mesh="index_finger_1st_roll_join_19" pos="0.0 0.0 0.0" euler="-1.5707963267948966 0.0 -1.5707963267948966" rgba="0.941 0.941 0.941 1.0" group="1" />
        <geom type="mesh" mesh="index_finger_1st_roll_join_19" pos="0.0 0.0 0.0" euler="-1.5707963267948966 0.0 -1.5707963267948966" group="0" rgba="1 0 0 0" />
        <body name="index_finger-1st-pitch" pos="0.0 0.0 0.0" euler="0.0 0.0 0.0">
          <joint name="IndexFinger-1st-pitch" type="hinge" axis="0 1 0" range="-1.5707963267948966 0.0" />
          <geom type="mesh" mesh="index_finger-1st-pitch_10" group="1" contype="0" conaffinity="0" pos="0.0 0.0 0.0" euler="-1.5707963267948966 0.0 -1.5707963267948966" rgba="0.941 0.941 0.941 1.0" />
          <geom type="cylinder" size="0.012 0.02" pos="0.02 0 0" euler="0 1.5708 0" group="0" rgba="0 0 1 0.4" />
          <body name="index_finger-2st-pitch" pos="0.035 0.0 0.41" euler="0.0 0.0 0.0">
            <joint name="IndexFinger-2nd-pitch" type="hinge" axis="0 1 0" range="-1.5707963267948966 -0.05235987755982988" />
            <geom type="mesh" mesh="index_finger-2st-pitch_11" group="1" contype="0" conaffinity="0" pos="0.0 0.0 0.0" euler="-1.5707963267948966 0.0 -1.5707963267948966" rgba="0.941 0.941 0.941 1.0" />
            <geom type="cylinder" size="0.012 0.02" pos="0.02 0 0" euler="0 1.5708 0" group="0" rgba="0 0 1 0.4" />
            <body name="index_finger-3st-pitch" pos="0.008 0.0 0.24" euler="0.0 0.0 0.0">
              <joint name="IndexFinger-3rd-pitch" type="hinge" axis="0 1 0" range="-1.5707963267948966 0.0" />
              <geom type="mesh" mesh="index_finger-3st-pitch_12" group="1" contype="0" conaffinity="0" pos="0.0 0.0 0.0" euler="-1.5707963267948966 0.0 -1.5707963267948966" rgba="0.941 0.941 0.941 1.0" />
              <geom type="cylinder" size="0.012 0.02" pos="0.02 0 0" euler="0 1.5708 0" group="0" rgba="0 0 1 0.4" />

              <site name="index_sensor_0_1" pos="0.03   0.03   0.275" size="0.01" rgba="1 0 0 1"/>
              <site name="index_sensor_0_2" pos="0.03   0      0.28 " size="0.01" rgba="1 0 0 1"/>
              <site name="index_sensor_0_3" pos="0.03   -0.03  0.275" size="0.01" rgba="1 0 0 1"/>
              <site name="index_sensor_1_1" pos="0      0.03   0.275" size="0.01" rgba="1 0 0 1"/>
              <site name="index_sensor_1_2" pos="0      0      0.275" size="0.01" rgba="1 0 0 1"/>
              <site name="index_sensor_1_3" pos="0      -0.03  0.275" size="0.01" rgba="1 0 0 1"/>
              <site name="index_sensor_2_1" pos="-0.03  0.03   0.26" size="0.01" rgba="1 0 0 1"/>
              <site name="index_sensor_2_2" pos="-0.03  0      0.26" size="0.01" rgba="1 0 0 1"/>
              <site name="index_sensor_2_3" pos="-0.03  -0.03  0.26" size="0.01" rgba="1 0 0 1"/>
              <site name="index_sensor_3_1" pos="-0.045 0.03   0.23" size="0.01" rgba="1 0 0 1"/>
              <site name="index_sensor_3_2" pos="-0.045 0      0.23" size="0.01" rgba="1 0 0 1"/>
              <site name="index_sensor_3_3" pos="-0.045 -0.03  0.23" size="0.01" rgba="1 0 0 1"/>
              <site name="index_sensor_4_1" pos="-0.05  0.03   0.2" size="0.01" rgba="1 0 0 1"/>
              <site name="index_sensor_4_2" pos="-0.05  0      0.2" size="0.01" rgba="1 0 0 1"/>
              <site name="index_sensor_4_3" pos="-0.05  -0.03  0.2" size="0.01" rgba="1 0 0 1"/>
              <site name="index_sensor_5_1" pos="-0.06  0.03   0.17" size="0.01" rgba="1 0 0 1"/>
              <site name="index_sensor_5_2" pos="-0.06  0      0.17" size="0.01" rgba="1 0 0 1"/>
              <site name="index_sensor_5_3" pos="-0.06  -0.03  0.17" size="0.01" rgba="1 0 0 1"/>
              <site name="index_sensor_6_1" pos="-0.065 0.03   0.14" size="0.01" rgba="1 0 0 1"/>
              <site name="index_sensor_6_2" pos="-0.065 0      0.14" size="0.01" rgba="1 0 0 1"/>
              <site name="index_sensor_6_3" pos="-0.065 -0.03  0.14" size="0.01" rgba="1 0 0 1"/>            
            </body>
          </body>
        </body>
      </body>
      <body name="new_link_4" pos="-0.07 -0.317 0.267" euler="0.0 0.0 3.141592653589793">
        <joint name="thumb_1st_yaw" type="hinge" axis="0 0 1" range="-0.5235987755982988 1.5707963267948966" />
        <geom type="mesh" mesh="thumb_1st_yaw_join_20" pos="0.0 0.0 0.0" euler="1.5707963267948966 0.0 1.5707963267948966" rgba="0.941 0.941 0.941 1.0" group="1" />
        <geom type="mesh" mesh="thumb_1st_yaw_join_20" pos="0.0 0.0 0.0" euler="1.5707963267948966 0.0 1.5707963267948966" group="0" rgba="1 0 0 0" />
        <body name="thumb-link" pos="0.0 0.0 0.0" euler="0.0 0.0 0.0">
          <joint name="Thumb-1st-pitch" type="hinge" axis="0 1 0" range="-1.5707963267948966 0.0" />
          <geom type="mesh" mesh="thumb-link_13" group="1" contype="0" conaffinity="0" pos="0.0 0.0 0.0" euler="-1.5707963267948966 -3.141592653589793 -1.5707963267948966" rgba="0.941 0.941 0.941 1.0" />
          <geom type="cylinder" size="0.012 0.02" pos="0.02 0 0" euler="0 1.5708 0" group="0" rgba="0 0 1 0.4" />
          <body name="new_link_11" pos="0.44 0.0 -0.035" euler="0.0 0.0 0.0">
            <joint name="Thumb-2nd-pitch" type="hinge" axis="0 1 0" range="-1.5707963267948966 0.0" />
            <geom type="mesh" mesh="new_link_11_14" group="1" contype="0" conaffinity="0" pos="0.0 0.0 0.0" euler="1.5707963267948966 0.0 1.5707963267948966" rgba="0.941 0.941 0.941 1.0" />
            <geom type="cylinder" size="0.012 0.02" pos="0.02 0 0" euler="0 1.5708 0" group="0" rgba="0 0 1 0.4" />
            <body name="new_link_15" pos="0.24 0.0 -0.008" euler="0.0 0.0 0.0">
              <joint name="Thumb-3rd-pitch" type="hinge" axis="0 1 0" range="-1.5707963267948966 0.0" />
              <geom type="mesh" mesh="new_link_15_15" group="1" contype="0" conaffinity="0" pos="0.0 0.0 0.0" euler="1.5707963267948966 0.0 1.5707963267948966" rgba="0.941 0.941 0.941 1.0" />
              <geom type="cylinder" size="0.012 0.02" pos="0.02 0 0" euler="0 1.5708 0" group="0" rgba="0 0 1 0.4" />

              <site name="thumb_sensor_0_1" pos="0.275 0.03   -0.03" size="0.01" rgba="1 0 0 1"/>
              <site name="thumb_sensor_0_2" pos="0.28     0   -0.03" size="0.01" rgba="1 0 0 1"/>
              <site name="thumb_sensor_0_3" pos="0.275 -0.03  -0.03" size="0.01" rgba="1 0 0 1"/>

              <site name="thumb_sensor_1_1" pos="0.275 0.03   0" size="0.01" rgba="1 0 0 1"/>
              <site name="thumb_sensor_1_2" pos="0.275 0      0" size="0.01" rgba="1 0 0 1"/>
              <site name="thumb_sensor_1_3" pos="0.275 -0.03  0" size="0.01" rgba="1 0 0 1"/>

              <site name="thumb_sensor_2_1" pos="0.26 0.03   0.03" size="0.01" rgba="1 0 0 1"/>
              <site name="thumb_sensor_2_2" pos="0.26 0      0.03" size="0.01" rgba="1 0 0 1"/>
              <site name="thumb_sensor_2_3" pos="0.26 -0.03  0.03" size="0.01" rgba="1 0 0 1"/>

              <site name="thumb_sensor_3_1" pos="0.23 0.03   0.045" size="0.01" rgba="1 0 0 1"/>
              <site name="thumb_sensor_3_2" pos="0.23 0      0.045" size="0.01" rgba="1 0 0 1"/>
              <site name="thumb_sensor_3_3" pos="0.23 -0.03   0.045" size="0.01" rgba="1 0 0 1"/>

              <site name="thumb_sensor_4_1" pos="0.2 0.03   0.05" size="0.01" rgba="1 0 0 1"/>
              <site name="thumb_sensor_4_2" pos="0.2 0      0.05" size="0.01" rgba="1 0 0 1"/>
              <site name="thumb_sensor_4_3" pos="0.2 -0.03  0.05" size="0.01" rgba="1 0 0 1"/>
              <site name="thumb_sensor_5_1" pos="0.17 0.03  0.06" size="0.01" rgba="1 0 0 1"/>
              <site name="thumb_sensor_5_2" pos="0.17 0     0.06" size="0.01" rgba="1 0 0 1"/>
              <site name="thumb_sensor_5_3" pos="0.17 -0.03 0.06" size="0.01" rgba="1 0 0 1"/>
              <site name="thumb_sensor_6_1" pos="0.14 0.03  0.065" size="0.01" rgba="1 0 0 1"/>
              <site name="thumb_sensor_6_2" pos="0.14 0     0.065" size="0.01" rgba="1 0 0 1"/>
              <site name="thumb_sensor_6_3" pos="0.14 -0.03 0.065" size="0.01" rgba="1 0 0 1"/>

              <!-- <site name="debug_sensor" type="box" pos="0.045 0 0" size="0.1 0.1 0.1" rgba="0 1 0 0.5" /> -->
            </body>
          </body>
        </body>
      </body>
    </body>
  </worldbody>
  <actuator>
          <position name="LittleFinger-1st_roll_act" joint="LittleFinger-1st_roll" kp="200" kv="20" ctrlrange="-0.17453292519943295 0.17453292519943295"/>
            <position name="LittleFinger-1st-pitch_act" joint="LittleFinger-1st-pitch" kp="200" kv="20" ctrlrange="-1.5707963267948966 0.0"/>
              <position name="LittleFinger-2nd-pitch_act" joint="LittleFinger-2nd-pitch" kp="200" kv="20" ctrlrange="-1.5707963267948966 0.0"/>
                <position name="LittleFinger-3rd-pitch_act" joint="LittleFinger-3rd-pitch" kp="200" kv="20" ctrlrange="-1.5707963267948966 0.0"/>
          <position name="RingFinger-1st_roll_act" joint="RingFinger-1st_roll" kp="200" kv="20" ctrlrange="-0.17453292519943295 0.17453292519943295"/>
            <position name="RingFinger-1st-pitch_act" joint="RingFinger-1st-pitch" kp="200" kv="20" ctrlrange="-1.5707963267948966 0.0"/>
              <position name="RingFinger-2nd-pitch_act" joint="RingFinger-2nd-pitch" kp="200" kv="20" ctrlrange="-1.5707963267948966 0.0"/>
                <position name="RingFinger-3rd-pitch_act" joint="RingFinger-3rd-pitch" kp="200" kv="20" ctrlrange="-1.5707963267948966 0.0"/>
          <position name="MiddleFinger_1st_roll_act" joint="MiddleFinger_1st_roll" kp="200" kv="20" ctrlrange="-0.17453292519943295 0.17453292519943295"/>
            <position name="MiddleFinger-1st-pitch_act" joint="MiddleFinger-1st-pitch" kp="200" kv="20" ctrlrange="-1.5707963267948966 0.0"/>
              <position name="MiddleFinger-2nd-pitch_act" joint="MiddleFinger-2nd-pitch" kp="200" kv="20" ctrlrange="-1.5707963267948966 0.0"/>
                <position name="MiddleFinger-3rd-pitch_act" joint="MiddleFinger-3rd-pitch" kp="200" kv="20" ctrlrange="-1.5707963267948966 -0.03490658503988659"/>
          <position name="IndexFinger_1st_roll_act" joint="IndexFinger_1st_roll" kp="200" kv="20" ctrlrange="-0.17453292519943295 0.17453292519943295"/>
            <position name="IndexFinger-1st-pitch_act" joint="IndexFinger-1st-pitch" kp="200" kv="20" ctrlrange="-1.5707963267948966 0.0"/>
              <position name="IndexFinger-2nd-pitch_act" joint="IndexFinger-2nd-pitch" kp="200" kv="20" ctrlrange="-1.5707963267948966 -0.05235987755982988"/>
                <position name="IndexFinger-3rd-pitch_act" joint="IndexFinger-3rd-pitch" kp="200" kv="20" ctrlrange="-1.5707963267948966 0.0"/>
          <position name="thumb_1st_yaw_act" joint="thumb_1st_yaw" kp="200" kv="20" ctrlrange="-0.5235987755982988 1.5707963267948966"/>
            <position name="Thumb-1st-pitch_act" joint="Thumb-1st-pitch" kp="200" kv="20" ctrlrange="-1.5707963267948966 0.0"/>
              <position name="Thumb-2nd-pitch_act" joint="Thumb-2nd-pitch" kp="200" kv="20" ctrlrange="-1.5707963267948966 0.0"/>
                <position name="Thumb-3rd-pitch_act" joint="Thumb-3rd-pitch" kp="200" kv="20" ctrlrange="-1.5707963267948966 0.0"/>
  </actuator>
  <sensor>
    <touch name="sensor_Little_1_1" site="Little_sensor_1_1" />
    <touch name="sensor_Ring_1_1" site="Ring_sensor_1_1" />
    <touch name="sensor_Middle_1_1" site="Middle_sensor_1_1" />
    <touch name="sensor_index_1_1" site="index_sensor_1_1" />
    <touch name="sensor_thumb_1_1" site="thumb_sensor_4_3" />
  </sensor>
</mujoco>
</mujoco>
